
Exception in thread django-main-thread:
Traceback (most recent call last):
  File "C:\Users\Gina\AppData\Local\Programs\Python\Python36-32\lib\threading.py", line 916, in _bootstrap_inner
    self.run()
  File "C:\Users\Gina\AppData\Local\Programs\Python\Python36-32\lib\threading.py", line 864, in run
    self._target(*self._args, **self._kwargs)
  File "C:\Users\Gina\PycharmProjects\Kivy\venv\lib\site-packages\django\utils\autoreload.py", line 53, in wrapper
    fn(*args, **kwargs)
  File "C:\Users\Gina\PycharmProjects\Kivy\venv\lib\site-packages\django\core\management\commands\runserver.py", line 117, in inner_run
    self.check(display_num_errors=True)
  File "C:\Users\Gina\PycharmProjects\Kivy\venv\lib\site-packages\django\core\management\base.py", line 395, in check
    include_deployment_checks=include_deployment_checks,
  File "C:\Users\Gina\PycharmProjects\Kivy\venv\lib\site-packages\django\core\management\base.py", line 382, in _run_checks
    return checks.run_checks(**kwargs)
  File "C:\Users\Gina\PycharmProjects\Kivy\venv\lib\site-packages\django\core\checks\registry.py", line 72, in run_checks
    new_errors = check(app_configs=app_configs)
  File "C:\Users\Gina\PycharmProjects\Kivy\venv\lib\site-packages\django\core\checks\urls.py", line 40, in check_url_namespaces_unique
    all_namespaces = _load_all_namespaces(resolver)
  File "C:\Users\Gina\PycharmProjects\Kivy\venv\lib\site-packages\django\core\checks\urls.py", line 57, in _load_all_namespaces
    url_patterns = getattr(resolver, 'url_patterns', [])
  File "C:\Users\Gina\PycharmProjects\Kivy\venv\lib\site-packages\django\utils\functional.py", line 48, in __get__
    res = instance.__dict__[self.name] = self.func(instance)
  File "C:\Users\Gina\PycharmProjects\Kivy\venv\lib\site-packages\django\urls\resolvers.py", line 588, in url_patterns
    patterns = getattr(self.urlconf_module, "urlpatterns", self.urlconf_module)
  File "C:\Users\Gina\PycharmProjects\Kivy\venv\lib\site-packages\django\utils\functional.py", line 48, in __get__
    res = instance.__dict__[self.name] = self.func(instance)
  File "C:\Users\Gina\PycharmProjects\Kivy\venv\lib\site-packages\django\urls\resolvers.py", line 581, in urlconf_module
    return import_module(self.urlconf_name)
  File "C:\Users\Gina\AppData\Local\Programs\Python\Python36-32\lib\importlib\__init__.py", line 126, in import_module
    return _bootstrap._gcd_import(name[level:], package, level)
  File "<frozen importlib._bootstrap>", line 994, in _gcd_import
  File "<frozen importlib._bootstrap>", line 971, in _find_and_load
  File "<frozen importlib._bootstrap>", line 955, in _find_and_load_unlocked
  File "<frozen importlib._bootstrap>", line 665, in _load_unlocked
  File "<frozen importlib._bootstrap_external>", line 674, in exec_module
  File "<frozen importlib._bootstrap_external>", line 781, in get_code
  File "<frozen importlib._bootstrap_external>", line 741, in source_to_code
  File "<frozen importlib._bootstrap>", line 219, in _call_with_frames_removed
  File "C:\Users\Gina\PycharmProjects\Django-DerekBanas\sampsite\sampsite\urls.py", line 31
    path('randomnumber' int('\%d'), random_number),
                          ^
SyntaxError: invalid syntax

C:\Users\Gina\PycharmProjects\Django-DerekBanas\sampsite\sampsite\urls.py changed, reloading.
Watching for file changes with StatReloader
Performing system checks...

System check identified no issues (0 silenced).

You have 17 unapplied migration(s). Your project may not work properly until you apply the migrations for app(s): admin, auth, contenttypes, sessions.
Run 'python manage.py migrate' to apply them.
April 22, 2020 - 20:50:51
Django version 3.0.5, using settings 'sampsite.settings'
Starting development server at http://127.0.0.1:8000/
Quit the server with CTRL-BREAK.
[22/Apr/2020 20:52:15] "GET /randomnumber HTTP/1.1" 200 45
C:\Users\Gina\PycharmProjects\Django-DerekBanas\sampsite\sampsite\views.py changed, reloading.
Watching for file changes with StatReloader
Performing system checks...

System check identified no issues (0 silenced).

You have 17 unapplied migration(s). Your project may not work properly until you apply the migrations for app(s): admin, auth, contenttypes, sessions.
Run 'python manage.py migrate' to apply them.
April 22, 2020 - 21:04:41
Django version 3.0.5, using settings 'sampsite.settings'
Starting development server at http://127.0.0.1:8000/
Quit the server with CTRL-BREAK.
[22/Apr/2020 21:13:59] "GET /randomnumber HTTP/1.1" 200 45
C:\Users\Gina\PycharmProjects\Django-DerekBanas\sampsite\sampsite\views.py changed, reloading.
Watching for file changes with StatReloader
Performing system checks...

System check identified no issues (0 silenced).

You have 17 unapplied migration(s). Your project may not work properly until you apply the migrations for app(s): admin, auth, contenttypes, sessions.
Run 'python manage.py migrate' to apply them.
April 22, 2020 - 21:14:05
Django version 3.0.5, using settings 'sampsite.settings'
Starting development server at http://127.0.0.1:8000/
Quit the server with CTRL-BREAK.
C:\Users\Gina\PycharmProjects\Django-DerekBanas\sampsite\sampsite\urls.py changed, reloading.
Watching for file changes with StatReloader
Performing system checks...

Exception in thread django-main-thread:
Traceback (most recent call last):
  File "C:\Users\Gina\AppData\Local\Programs\Python\Python36-32\lib\threading.py", line 916, in _bootstrap_inner
    self.run()
  File "C:\Users\Gina\AppData\Local\Programs\Python\Python36-32\lib\threading.py", line 864, in run
    self._target(*self._args, **self._kwargs)
  File "C:\Users\Gina\PycharmProjects\Kivy\venv\lib\site-packages\django\utils\autoreload.py", line 53, in wrapper
    fn(*args, **kwargs)
  File "C:\Users\Gina\PycharmProjects\Kivy\venv\lib\site-packages\django\core\management\commands\runserver.py", line 117, in inner_run
    self.check(display_num_errors=True)
  File "C:\Users\Gina\PycharmProjects\Kivy\venv\lib\site-packages\django\core\management\base.py", line 395, in check
    include_deployment_checks=include_deployment_checks,
  File "C:\Users\Gina\PycharmProjects\Kivy\venv\lib\site-packages\django\core\management\base.py", line 382, in _run_checks
    return checks.run_checks(**kwargs)
  File "C:\Users\Gina\PycharmProjects\Kivy\venv\lib\site-packages\django\core\checks\registry.py", line 72, in run_checks
    new_errors = check(app_configs=app_configs)
  File "C:\Users\Gina\PycharmProjects\Kivy\venv\lib\site-packages\django\core\checks\urls.py", line 40, in check_url_namespaces_unique
    all_namespaces = _load_all_namespaces(resolver)
  File "C:\Users\Gina\PycharmProjects\Kivy\venv\lib\site-packages\django\core\checks\urls.py", line 57, in _load_all_namespaces
    url_patterns = getattr(resolver, 'url_patterns', [])
  File "C:\Users\Gina\PycharmProjects\Kivy\venv\lib\site-packages\django\utils\functional.py", line 48, in __get__
    res = instance.__dict__[self.name] = self.func(instance)
  File "C:\Users\Gina\PycharmProjects\Kivy\venv\lib\site-packages\django\urls\resolvers.py", line 588, in url_patterns
    patterns = getattr(self.urlconf_module, "urlpatterns", self.urlconf_module)
  File "C:\Users\Gina\PycharmProjects\Kivy\venv\lib\site-packages\django\utils\functional.py", line 48, in __get__
    res = instance.__dict__[self.name] = self.func(instance)
  File "C:\Users\Gina\PycharmProjects\Kivy\venv\lib\site-packages\django\urls\resolvers.py", line 581, in urlconf_module
    return import_module(self.urlconf_name)
  File "C:\Users\Gina\AppData\Local\Programs\Python\Python36-32\lib\importlib\__init__.py", line 126, in import_module
    return _bootstrap._gcd_import(name[level:], package, level)
  File "<frozen importlib._bootstrap>", line 994, in _gcd_import
  File "<frozen importlib._bootstrap>", line 971, in _find_and_load
  File "<frozen importlib._bootstrap>", line 955, in _find_and_load_unlocked
  File "<frozen importlib._bootstrap>", line 665, in _load_unlocked
  File "<frozen importlib._bootstrap_external>", line 674, in exec_module
  File "<frozen importlib._bootstrap_external>", line 781, in get_code
  File "<frozen importlib._bootstrap_external>", line 741, in source_to_code
  File "<frozen importlib._bootstrap>", line 219, in _call_with_frames_removed
  File "C:\Users\Gina\PycharmProjects\Django-DerekBanas\sampsite\sampsite\urls.py", line 31
    path('randomnumber'\d+, random_number),
                                          ^
SyntaxError: unexpected character after line continuation character

C:\Users\Gina\PycharmProjects\Django-DerekBanas\sampsite\sampsite\urls.py changed, reloading.
Watching for file changes with StatReloader
Performing system checks...

Exception in thread django-main-thread:
Traceback (most recent call last):
  File "C:\Users\Gina\AppData\Local\Programs\Python\Python36-32\lib\threading.py", line 916, in _bootstrap_inner
    self.run()
  File "C:\Users\Gina\AppData\Local\Programs\Python\Python36-32\lib\threading.py", line 864, in run
    self._target(*self._args, **self._kwargs)
  File "C:\Users\Gina\PycharmProjects\Kivy\venv\lib\site-packages\django\utils\autoreload.py", line 53, in wrapper
    fn(*args, **kwargs)
  File "C:\Users\Gina\PycharmProjects\Kivy\venv\lib\site-packages\django\core\management\commands\runserver.py", line 117, in inner_run
    self.check(display_num_errors=True)
  File "C:\Users\Gina\PycharmProjects\Kivy\venv\lib\site-packages\django\core\management\base.py", line 395, in check
    include_deployment_checks=include_deployment_checks,
  File "C:\Users\Gina\PycharmProjects\Kivy\venv\lib\site-packages\django\core\management\base.py", line 382, in _run_checks
    return checks.run_checks(**kwargs)
  File "C:\Users\Gina\PycharmProjects\Kivy\venv\lib\site-packages\django\core\checks\registry.py", line 72, in run_checks
    new_errors = check(app_configs=app_configs)
  File "C:\Users\Gina\PycharmProjects\Kivy\venv\lib\site-packages\django\core\checks\urls.py", line 40, in check_url_namespaces_unique
    all_namespaces = _load_all_namespaces(resolver)
  File "C:\Users\Gina\PycharmProjects\Kivy\venv\lib\site-packages\django\core\checks\urls.py", line 57, in _load_all_namespaces
    url_patterns = getattr(resolver, 'url_patterns', [])
  File "C:\Users\Gina\PycharmProjects\Kivy\venv\lib\site-packages\django\utils\functional.py", line 48, in __get__
    res = instance.__dict__[self.name] = self.func(instance)
  File "C:\Users\Gina\PycharmProjects\Kivy\venv\lib\site-packages\django\urls\resolvers.py", line 588, in url_patterns
    patterns = getattr(self.urlconf_module, "urlpatterns", self.urlconf_module)
  File "C:\Users\Gina\PycharmProjects\Kivy\venv\lib\site-packages\django\utils\functional.py", line 48, in __get__
    res = instance.__dict__[self.name] = self.func(instance)
  File "C:\Users\Gina\PycharmProjects\Kivy\venv\lib\site-packages\django\urls\resolvers.py", line 581, in urlconf_module
    return import_module(self.urlconf_name)
  File "C:\Users\Gina\AppData\Local\Programs\Python\Python36-32\lib\importlib\__init__.py", line 126, in import_module
    return _bootstrap._gcd_import(name[level:], package, level)
  File "<frozen importlib._bootstrap>", line 994, in _gcd_import
  File "<frozen importlib._bootstrap>", line 971, in _find_and_load
  File "<frozen importlib._bootstrap>", line 955, in _find_and_load_unlocked
  File "<frozen importlib._bootstrap>", line 665, in _load_unlocked
  File "<frozen importlib._bootstrap_external>", line 674, in exec_module
  File "<frozen importlib._bootstrap_external>", line 781, in get_code
  File "<frozen importlib._bootstrap_external>", line 741, in source_to_code
  File "<frozen importlib._bootstrap>", line 219, in _call_with_frames_removed
  File "C:\Users\Gina\PycharmProjects\Django-DerekBanas\sampsite\sampsite\urls.py", line 31
    path('randomnumber'\d+/, random_number),
                                           ^
SyntaxError: unexpected character after line continuation character

C:\Users\Gina\PycharmProjects\Django-DerekBanas\sampsite\sampsite\urls.py changed, reloading.
Watching for file changes with StatReloader
Performing system checks...

System check identified no issues (0 silenced).

You have 17 unapplied migration(s). Your project may not work properly until you apply the migrations for app(s): admin, auth, contenttypes, sessions.
Run 'python manage.py migrate' to apply them.
April 22, 2020 - 21:23:23
Django version 3.0.5, using settings 'sampsite.settings'
Starting development server at http://127.0.0.1:8000/
Quit the server with CTRL-BREAK.
C:\Users\Gina\PycharmProjects\Django-DerekBanas\sampsite\sampsite\settings.py changed, reloading.
Watching for file changes with StatReloader
Performing system checks...

System check identified no issues (0 silenced).

You have 17 unapplied migration(s). Your project may not work properly until you apply the migrations for app(s): admin, auth, contenttypes, sessions.
Run 'python manage.py migrate' to apply them.
April 22, 2020 - 22:03:18
Django version 3.0.5, using settings 'sampsite.settings'
Starting development server at http://127.0.0.1:8000/
Quit the server with CTRL-BREAK.
C:\Users\Gina\PycharmProjects\Django-DerekBanas\sampsite\sampsite\settings.py changed, reloading.
Watching for file changes with StatReloader
Performing system checks...

System check identified no issues (0 silenced).

You have 17 unapplied migration(s). Your project may not work properly until you apply the migrations for app(s): admin, auth, contenttypes, sessions.
Run 'python manage.py migrate' to apply them.
April 22, 2020 - 22:09:17
Django version 3.0.5, using settings 'sampsite.settings'
Starting development server at http://127.0.0.1:8000/
Quit the server with CTRL-BREAK.
C:\Users\Gina\PycharmProjects\Django-DerekBanas\sampsite\sampsite\settings.py changed, reloading.
Watching for file changes with StatReloader
Performing system checks...

System check identified no issues (0 silenced).

You have 17 unapplied migration(s). Your project may not work properly until you apply the migrations for app(s): admin, auth, contenttypes, sessions.
Run 'python manage.py migrate' to apply them.
April 22, 2020 - 22:10:22
Django version 3.0.5, using settings 'sampsite.settings'
Starting development server at http://127.0.0.1:8000/
Quit the server with CTRL-BREAK.
[22/Apr/2020 22:45:21] "GET /randomnumber HTTP/1.1" 200 45
Not Found: /polls
[22/Apr/2020 22:45:36] "GET /polls HTTP/1.1" 404 2279
Not Found: /index
[22/Apr/2020 22:45:47] "GET /index HTTP/1.1" 404 2279
Not Found: /index
[22/Apr/2020 22:47:28] "GET /index HTTP/1.1" 404 2279
Not Found: /index
[22/Apr/2020 22:47:32] "GET /index HTTP/1.1" 404 2279
Not Found: /polls
[22/Apr/2020 22:47:40] "GET /polls HTTP/1.1" 404 2279
Not Found: /polls
[22/Apr/2020 22:48:12] "GET /polls HTTP/1.1" 404 2279
Not Found: /index
[22/Apr/2020 22:48:18] "GET /index HTTP/1.1" 404 2279
C:\Users\Gina\PycharmProjects\Django-DerekBanas\sampsite\sampsite\urls.py changed, reloading.
Watching for file changes with StatReloader
Performing system checks...

System check identified no issues (0 silenced).

You have 17 unapplied migration(s). Your project may not work properly until you apply the migrations for app(s): admin, auth, contenttypes, sessions.
Run 'python manage.py migrate' to apply them.
April 22, 2020 - 22:55:11
Django version 3.0.5, using settings 'sampsite.settings'
Starting development server at http://127.0.0.1:8000/
Quit the server with CTRL-BREAK.
C:\Users\Gina\PycharmProjects\Django-DerekBanas\sampsite\sampsite\urls.py changed, reloading.
Watching for file changes with StatReloader
Performing system checks...

System check identified no issues (0 silenced).

You have 17 unapplied migration(s). Your project may not work properly until you apply the migrations for app(s): admin, auth, contenttypes, sessions.
Run 'python manage.py migrate' to apply them.
April 22, 2020 - 23:01:21
Django version 3.0.5, using settings 'sampsite.settings'
Starting development server at http://127.0.0.1:8000/
Quit the server with CTRL-BREAK.
[22/Apr/2020 23:03:31] "GET /randomnumber HTTP/1.1" 200 45
[22/Apr/2020 23:05:38] "GET /polls HTTP/1.1" 301 0
[22/Apr/2020 23:05:38] "GET /polls/ HTTP/1.1" 200 30
C:\Users\Gina\PycharmProjects\Django-DerekBanas\sampsite\sampsite\urls.py changed, reloading.
Watching for file changes with StatReloader
Performing system checks...

System check identified no issues (0 silenced).

You have 17 unapplied migration(s). Your project may not work properly until you apply the migrations for app(s): admin, auth, contenttypes, sessions.
Run 'python manage.py migrate' to apply them.
April 22, 2020 - 23:14:39
Django version 3.0.5, using settings 'sampsite.settings'
Starting development server at http://127.0.0.1:8000/
Quit the server with CTRL-BREAK.
Not Found: /random
[22/Apr/2020 23:14:51] "GET /random HTTP/1.1" 404 2403
Not Found: /random/
[22/Apr/2020 23:15:00] "GET /random/ HTTP/1.1" 404 2406
Not Found: /random/
[22/Apr/2020 23:16:39] "GET /random/ HTTP/1.1" 404 2406
Not Found: /random/
[22/Apr/2020 23:16:47] "GET /random/ HTTP/1.1" 404 2406
[22/Apr/2020 23:16:58] "GET /random/1000 HTTP/1.1" 200 47
Internal Server Error: /random/0
Traceback (most recent call last):
  File "C:\Users\Gina\PycharmProjects\Kivy\venv\lib\site-packages\django\core\handlers\exception.py", line 34, in inner
    response = get_response(request)
  File "C:\Users\Gina\PycharmProjects\Kivy\venv\lib\site-packages\django\core\handlers\base.py", line 115, in _get_response
    response = self.process_exception_by_middleware(e, request)
  File "C:\Users\Gina\PycharmProjects\Kivy\venv\lib\site-packages\django\core\handlers\base.py", line 113, in _get_response
    response = wrapped_callback(request, *callback_args, **callback_kwargs)
  File "C:\Users\Gina\PycharmProjects\Django-DerekBanas\sampsite\sampsite\views.py", line 23, in random_number
    random_num = random.randrange(0, int(max_rand))
  File "C:\Users\Gina\AppData\Local\Programs\Python\Python36-32\lib\random.py", line 199, in randrange
    raise ValueError("empty range for randrange() (%d,%d, %d)" % (istart, istop, width))
ValueError: empty range for randrange() (0,0, 0)
[22/Apr/2020 23:17:34] "GET /random/0 HTTP/1.1" 500 74677
[22/Apr/2020 23:17:49] "GET /random/1 HTTP/1.1" 200 42
C:\Users\Gina\PycharmProjects\Django-DerekBanas\sampsite\sampsite\urls.py changed, reloading.
Watching for file changes with StatReloader
Performing system checks...

System check identified no issues (0 silenced).

You have 17 unapplied migration(s). Your project may not work properly until you apply the migrations for app(s): admin, auth, contenttypes, sessions.
Run 'python manage.py migrate' to apply them.
April 22, 2020 - 23:24:22
Django version 3.0.5, using settings 'sampsite.settings'
Starting development server at http://127.0.0.1:8000/
Quit the server with CTRL-BREAK.
Not Found: /random/1000
[22/Apr/2020 23:24:36] "GET /random/1000 HTTP/1.1" 404 2429
Not Found: /random/
[22/Apr/2020 23:24:57] "GET /random/ HTTP/1.1" 404 2417
C:\Users\Gina\PycharmProjects\Django-DerekBanas\sampsite\sampsite\urls.py changed, reloading.
Watching for file changes with StatReloader
Performing system checks...

System check identified no issues (0 silenced).

You have 17 unapplied migration(s). Your project may not work properly until you apply the migrations for app(s): admin, auth, contenttypes, sessions.
Run 'python manage.py migrate' to apply them.
April 22, 2020 - 23:26:40
Django version 3.0.5, using settings 'sampsite.settings'
Starting development server at http://127.0.0.1:8000/
Quit the server with CTRL-BREAK.
[22/Apr/2020 23:26:41] "GET /random/ HTTP/1.1" 200 45
[22/Apr/2020 23:26:51] "GET /random/1000 HTTP/1.1" 200 47
C:\Users\Gina\PycharmProjects\Django-DerekBanas\sampsite\sampsite\urls.py changed, reloading.
Watching for file changes with StatReloader
Performing system checks...

System check identified no issues (0 silenced).

You have 17 unapplied migration(s). Your project may not work properly until you apply the migrations for app(s): admin, auth, contenttypes, sessions.
Run 'python manage.py migrate' to apply them.
April 22, 2020 - 23:29:58
Django version 3.0.5, using settings 'sampsite.settings'
Starting development server at http://127.0.0.1:8000/
Quit the server with CTRL-BREAK.
C:\Users\Gina\PycharmProjects\Django-DerekBanas\sampsite\sampsite\urls.py changed, reloading.
Watching for file changes with StatReloader
Performing system checks...

System check identified no issues (0 silenced).

You have 17 unapplied migration(s). Your project may not work properly until you apply the migrations for app(s): admin, auth, contenttypes, sessions.
Run 'python manage.py migrate' to apply them.
April 23, 2020 - 15:35:56
Django version 3.0.5, using settings 'sampsite.settings'
Starting development server at http://127.0.0.1:8000/
Quit the server with CTRL-BREAK.
[23/Apr/2020 15:35:59] "GET /random/1000 HTTP/1.1" 200 47
C:\Users\Gina\PycharmProjects\Django-DerekBanas\sampsite\sampsite\urls.py changed, reloading.
Watching for file changes with StatReloader
Performing system checks...

System check identified no issues (0 silenced).

You have 17 unapplied migration(s). Your project may not work properly until you apply the migrations for app(s): admin, auth, contenttypes, sessions.
Run 'python manage.py migrate' to apply them.
April 23, 2020 - 15:38:39
Django version 3.0.5, using settings 'sampsite.settings'
Starting development server at http://127.0.0.1:8000/
Quit the server with CTRL-BREAK.
[23/Apr/2020 15:38:40] "GET /random/1000 HTTP/1.1" 200 23
[23/Apr/2020 15:38:48] "GET /random/1000 HTTP/1.1" 200 23
[23/Apr/2020 15:38:55] "GET /random/1000 HTTP/1.1" 200 23
[23/Apr/2020 15:39:04] "GET /random/ HTTP/1.1" 200 23
[23/Apr/2020 15:39:15] "GET /random/1000 HTTP/1.1" 200 23
[23/Apr/2020 15:39:18] "GET /random/1000 HTTP/1.1" 200 23
[23/Apr/2020 15:39:58] "GET /polls/ HTTP/1.1" 200 23
C:\Users\Gina\PycharmProjects\Django-DerekBanas\sampsite\sampsite\urls.py changed, reloading.
Watching for file changes with StatReloader
Performing system checks...

System check identified no issues (0 silenced).

You have 17 unapplied migration(s). Your project may not work properly until you apply the migrations for app(s): admin, auth, contenttypes, sessions.
Run 'python manage.py migrate' to apply them.
April 23, 2020 - 15:41:29
Django version 3.0.5, using settings 'sampsite.settings'
Starting development server at http://127.0.0.1:8000/
Quit the server with CTRL-BREAK.
[23/Apr/2020 15:41:31] "GET /polls/ HTTP/1.1" 200 30
[23/Apr/2020 15:41:50] "GET /random/1000 HTTP/1.1" 200 45
[23/Apr/2020 15:41:53] "GET /random/1000 HTTP/1.1" 200 45
[23/Apr/2020 15:41:55] "GET /random/1 HTTP/1.1" 200 45
[23/Apr/2020 15:41:58] "GET /random/1 HTTP/1.1" 200 45
[23/Apr/2020 15:42:04] "GET /random/1 HTTP/1.1" 200 45
[23/Apr/2020 15:42:06] "GET /random/1 HTTP/1.1" 200 45
[23/Apr/2020 15:42:07] "GET /random/1 HTTP/1.1" 200 45
[23/Apr/2020 15:42:41] "GET /random/0 HTTP/1.1" 200 45
[23/Apr/2020 15:42:44] "GET /random HTTP/1.1" 301 0
Not Found: /index
[23/Apr/2020 15:42:56] "GET /index HTTP/1.1" 404 2507
[23/Apr/2020 15:43:00] "GET /polls/ HTTP/1.1" 200 30
[23/Apr/2020 15:43:07] "GET /helloworld/ HTTP/1.1" 200 21
[23/Apr/2020 15:43:11] "GET /helloworld/ HTTP/1.1" 200 21
Not Found: /rootpage
[23/Apr/2020 15:43:38] "GET /rootpage HTTP/1.1" 404 2516
[23/Apr/2020 15:44:22] "GET /admin HTTP/1.1" 301 0
Internal Server Error: /admin/
Traceback (most recent call last):
  File "C:\Users\Gina\PycharmProjects\Kivy\venv\lib\site-packages\django\contrib\sessions\backends\base.py", line 199, in _get_session
    return self._session_cache
AttributeError: 'SessionStore' object has no attribute '_session_cache'

During handling of the above exception, another exception occurred:

Traceback (most recent call last):
  File "C:\Users\Gina\PycharmProjects\Kivy\venv\lib\site-packages\django\db\backends\utils.py", line 86, in _execute
    return self.cursor.execute(sql, params)
  File "C:\Users\Gina\PycharmProjects\Kivy\venv\lib\site-packages\django\db\backends\sqlite3\base.py", line 396, in execute
    return Database.Cursor.execute(self, query, params)
sqlite3.OperationalError: no such table: django_session

The above exception was the direct cause of the following exception:

Traceback (most recent call last):
  File "C:\Users\Gina\PycharmProjects\Kivy\venv\lib\site-packages\django\core\handlers\exception.py", line 34, in inner
    response = get_response(request)
  File "C:\Users\Gina\PycharmProjects\Kivy\venv\lib\site-packages\django\core\handlers\base.py", line 115, in _get_response
    response = self.process_exception_by_middleware(e, request)
  File "C:\Users\Gina\PycharmProjects\Kivy\venv\lib\site-packages\django\core\handlers\base.py", line 113, in _get_response
    response = wrapped_callback(request, *callback_args, **callback_kwargs)
  File "C:\Users\Gina\PycharmProjects\Kivy\venv\lib\site-packages\django\contrib\admin\sites.py", line 249, in wrapper
    return self.admin_view(view, cacheable)(*args, **kwargs)
  File "C:\Users\Gina\PycharmProjects\Kivy\venv\lib\site-packages\django\utils\decorators.py", line 130, in _wrapped_view
    response = view_func(request, *args, **kwargs)
  File "C:\Users\Gina\PycharmProjects\Kivy\venv\lib\site-packages\django\views\decorators\cache.py", line 44, in _wrapped_view_func
    response = view_func(request, *args, **kwargs)
  File "C:\Users\Gina\PycharmProjects\Kivy\venv\lib\site-packages\django\contrib\admin\sites.py", line 220, in inner
    if not self.has_permission(request):
  File "C:\Users\Gina\PycharmProjects\Kivy\venv\lib\site-packages\django\contrib\admin\sites.py", line 194, in has_permission
    return request.user.is_active and request.user.is_staff
  File "C:\Users\Gina\PycharmProjects\Kivy\venv\lib\site-packages\django\utils\functional.py", line 224, in inner
    self._setup()
  File "C:\Users\Gina\PycharmProjects\Kivy\venv\lib\site-packages\django\utils\functional.py", line 360, in _setup
    self._wrapped = self._setupfunc()
  File "C:\Users\Gina\PycharmProjects\Kivy\venv\lib\site-packages\django\contrib\auth\middleware.py", line 24, in <lambda>
    request.user = SimpleLazyObject(lambda: get_user(request))
  File "C:\Users\Gina\PycharmProjects\Kivy\venv\lib\site-packages\django\contrib\auth\middleware.py", line 12, in get_user
    request._cached_user = auth.get_user(request)
  File "C:\Users\Gina\PycharmProjects\Kivy\venv\lib\site-packages\django\contrib\auth\__init__.py", line 173, in get_user
    user_id = _get_user_session_key(request)
  File "C:\Users\Gina\PycharmProjects\Kivy\venv\lib\site-packages\django\contrib\auth\__init__.py", line 58, in _get_user_session_key
    return get_user_model()._meta.pk.to_python(request.session[SESSION_KEY])
  File "C:\Users\Gina\PycharmProjects\Kivy\venv\lib\site-packages\django\contrib\sessions\backends\base.py", line 64, in __getitem__
    return self._session[key]
  File "C:\Users\Gina\PycharmProjects\Kivy\venv\lib\site-packages\django\contrib\sessions\backends\base.py", line 204, in _get_session
    self._session_cache = self.load()
  File "C:\Users\Gina\PycharmProjects\Kivy\venv\lib\site-packages\django\contrib\sessions\backends\db.py", line 43, in load
    s = self._get_session_from_db()
  File "C:\Users\Gina\PycharmProjects\Kivy\venv\lib\site-packages\django\contrib\sessions\backends\db.py", line 34, in _get_session_from_db
    expire_date__gt=timezone.now()
  File "C:\Users\Gina\PycharmProjects\Kivy\venv\lib\site-packages\django\db\models\manager.py", line 82, in manager_method
    return getattr(self.get_queryset(), name)(*args, **kwargs)
  File "C:\Users\Gina\PycharmProjects\Kivy\venv\lib\site-packages\django\db\models\query.py", line 411, in get
    num = len(clone)
  File "C:\Users\Gina\PycharmProjects\Kivy\venv\lib\site-packages\django\db\models\query.py", line 258, in __len__
    self._fetch_all()
  File "C:\Users\Gina\PycharmProjects\Kivy\venv\lib\site-packages\django\db\models\query.py", line 1261, in _fetch_all
    self._result_cache = list(self._iterable_class(self))
  File "C:\Users\Gina\PycharmProjects\Kivy\venv\lib\site-packages\django\db\models\query.py", line 57, in __iter__
    results = compiler.execute_sql(chunked_fetch=self.chunked_fetch, chunk_size=self.chunk_size)
  File "C:\Users\Gina\PycharmProjects\Kivy\venv\lib\site-packages\django\db\models\sql\compiler.py", line 1151, in execute_sql
    cursor.execute(sql, params)
  File "C:\Users\Gina\PycharmProjects\Kivy\venv\lib\site-packages\django\db\backends\utils.py", line 100, in execute
    return super().execute(sql, params)
  File "C:\Users\Gina\PycharmProjects\Kivy\venv\lib\site-packages\django\db\backends\utils.py", line 68, in execute
    return self._execute_with_wrappers(sql, params, many=False, executor=self._execute)
  File "C:\Users\Gina\PycharmProjects\Kivy\venv\lib\site-packages\django\db\backends\utils.py", line 77, in _execute_with_wrappers
    return executor(sql, params, many, context)
  File "C:\Users\Gina\PycharmProjects\Kivy\venv\lib\site-packages\django\db\backends\utils.py", line 86, in _execute
    return self.cursor.execute(sql, params)
  File "C:\Users\Gina\PycharmProjects\Kivy\venv\lib\site-packages\django\db\utils.py", line 90, in __exit__
    raise dj_exc_value.with_traceback(traceback) from exc_value
  File "C:\Users\Gina\PycharmProjects\Kivy\venv\lib\site-packages\django\db\backends\utils.py", line 86, in _execute
    return self.cursor.execute(sql, params)
  File "C:\Users\Gina\PycharmProjects\Kivy\venv\lib\site-packages\django\db\backends\sqlite3\base.py", line 396, in execute
    return Database.Cursor.execute(self, query, params)
django.db.utils.OperationalError: no such table: django_session
[23/Apr/2020 15:44:35] "GET /admin/ HTTP/1.1" 500 195278
Internal Server Error: /admin/
Traceback (most recent call last):
  File "C:\Users\Gina\PycharmProjects\Kivy\venv\lib\site-packages\django\contrib\sessions\backends\base.py", line 199, in _get_session
    return self._session_cache
AttributeError: 'SessionStore' object has no attribute '_session_cache'

During handling of the above exception, another exception occurred:

Traceback (most recent call last):
  File "C:\Users\Gina\PycharmProjects\Kivy\venv\lib\site-packages\django\db\backends\utils.py", line 86, in _execute
    return self.cursor.execute(sql, params)
  File "C:\Users\Gina\PycharmProjects\Kivy\venv\lib\site-packages\django\db\backends\sqlite3\base.py", line 396, in execute
    return Database.Cursor.execute(self, query, params)
sqlite3.OperationalError: no such table: django_session

The above exception was the direct cause of the following exception:

Traceback (most recent call last):
  File "C:\Users\Gina\PycharmProjects\Kivy\venv\lib\site-packages\django\core\handlers\exception.py", line 34, in inner
    response = get_response(request)
  File "C:\Users\Gina\PycharmProjects\Kivy\venv\lib\site-packages\django\core\handlers\base.py", line 115, in _get_response
    response = self.process_exception_by_middleware(e, request)
  File "C:\Users\Gina\PycharmProjects\Kivy\venv\lib\site-packages\django\core\handlers\base.py", line 113, in _get_response
    response = wrapped_callback(request, *callback_args, **callback_kwargs)
  File "C:\Users\Gina\PycharmProjects\Kivy\venv\lib\site-packages\django\contrib\admin\sites.py", line 249, in wrapper
    return self.admin_view(view, cacheable)(*args, **kwargs)
  File "C:\Users\Gina\PycharmProjects\Kivy\venv\lib\site-packages\django\utils\decorators.py", line 130, in _wrapped_view
    response = view_func(request, *args, **kwargs)
  File "C:\Users\Gina\PycharmProjects\Kivy\venv\lib\site-packages\django\views\decorators\cache.py", line 44, in _wrapped_view_func
    response = view_func(request, *args, **kwargs)
  File "C:\Users\Gina\PycharmProjects\Kivy\venv\lib\site-packages\django\contrib\admin\sites.py", line 220, in inner
    if not self.has_permission(request):
  File "C:\Users\Gina\PycharmProjects\Kivy\venv\lib\site-packages\django\contrib\admin\sites.py", line 194, in has_permission
    return request.user.is_active and request.user.is_staff
  File "C:\Users\Gina\PycharmProjects\Kivy\venv\lib\site-packages\django\utils\functional.py", line 224, in inner
    self._setup()
  File "C:\Users\Gina\PycharmProjects\Kivy\venv\lib\site-packages\django\utils\functional.py", line 360, in _setup
    self._wrapped = self._setupfunc()
  File "C:\Users\Gina\PycharmProjects\Kivy\venv\lib\site-packages\django\contrib\auth\middleware.py", line 24, in <lambda>
    request.user = SimpleLazyObject(lambda: get_user(request))
  File "C:\Users\Gina\PycharmProjects\Kivy\venv\lib\site-packages\django\contrib\auth\middleware.py", line 12, in get_user
    request._cached_user = auth.get_user(request)
  File "C:\Users\Gina\PycharmProjects\Kivy\venv\lib\site-packages\django\contrib\auth\__init__.py", line 173, in get_user
    user_id = _get_user_session_key(request)
  File "C:\Users\Gina\PycharmProjects\Kivy\venv\lib\site-packages\django\contrib\auth\__init__.py", line 58, in _get_user_session_key
    return get_user_model()._meta.pk.to_python(request.session[SESSION_KEY])
  File "C:\Users\Gina\PycharmProjects\Kivy\venv\lib\site-packages\django\contrib\sessions\backends\base.py", line 64, in __getitem__
    return self._session[key]
  File "C:\Users\Gina\PycharmProjects\Kivy\venv\lib\site-packages\django\contrib\sessions\backends\base.py", line 204, in _get_session
    self._session_cache = self.load()
  File "C:\Users\Gina\PycharmProjects\Kivy\venv\lib\site-packages\django\contrib\sessions\backends\db.py", line 43, in load
    s = self._get_session_from_db()
  File "C:\Users\Gina\PycharmProjects\Kivy\venv\lib\site-packages\django\contrib\sessions\backends\db.py", line 34, in _get_session_from_db
    expire_date__gt=timezone.now()
  File "C:\Users\Gina\PycharmProjects\Kivy\venv\lib\site-packages\django\db\models\manager.py", line 82, in manager_method
    return getattr(self.get_queryset(), name)(*args, **kwargs)
  File "C:\Users\Gina\PycharmProjects\Kivy\venv\lib\site-packages\django\db\models\query.py", line 411, in get
    num = len(clone)
  File "C:\Users\Gina\PycharmProjects\Kivy\venv\lib\site-packages\django\db\models\query.py", line 258, in __len__
    self._fetch_all()
  File "C:\Users\Gina\PycharmProjects\Kivy\venv\lib\site-packages\django\db\models\query.py", line 1261, in _fetch_all
    self._result_cache = list(self._iterable_class(self))
  File "C:\Users\Gina\PycharmProjects\Kivy\venv\lib\site-packages\django\db\models\query.py", line 57, in __iter__
    results = compiler.execute_sql(chunked_fetch=self.chunked_fetch, chunk_size=self.chunk_size)
  File "C:\Users\Gina\PycharmProjects\Kivy\venv\lib\site-packages\django\db\models\sql\compiler.py", line 1151, in execute_sql
    cursor.execute(sql, params)
  File "C:\Users\Gina\PycharmProjects\Kivy\venv\lib\site-packages\django\db\backends\utils.py", line 100, in execute
    return super().execute(sql, params)
  File "C:\Users\Gina\PycharmProjects\Kivy\venv\lib\site-packages\django\db\backends\utils.py", line 68, in execute
    return self._execute_with_wrappers(sql, params, many=False, executor=self._execute)
  File "C:\Users\Gina\PycharmProjects\Kivy\venv\lib\site-packages\django\db\backends\utils.py", line 77, in _execute_with_wrappers
    return executor(sql, params, many, context)
  File "C:\Users\Gina\PycharmProjects\Kivy\venv\lib\site-packages\django\db\backends\utils.py", line 86, in _execute
    return self.cursor.execute(sql, params)
  File "C:\Users\Gina\PycharmProjects\Kivy\venv\lib\site-packages\django\db\utils.py", line 90, in __exit__
    raise dj_exc_value.with_traceback(traceback) from exc_value
  File "C:\Users\Gina\PycharmProjects\Kivy\venv\lib\site-packages\django\db\backends\utils.py", line 86, in _execute
    return self.cursor.execute(sql, params)
  File "C:\Users\Gina\PycharmProjects\Kivy\venv\lib\site-packages\django\db\backends\sqlite3\base.py", line 396, in execute
    return Database.Cursor.execute(self, query, params)
django.db.utils.OperationalError: no such table: django_session
[23/Apr/2020 15:44:35] "GET /admin/ HTTP/1.1" 500 195406
Traceback (most recent call last):
  File "C:\Users\Gina\AppData\Local\Programs\Python\Python36-32\lib\wsgiref\handlers.py", line 138, in run
    self.finish_response()
  File "C:\Users\Gina\AppData\Local\Programs\Python\Python36-32\lib\wsgiref\handlers.py", line 180, in finish_response
    self.write(data)
  File "C:\Users\Gina\AppData\Local\Programs\Python\Python36-32\lib\wsgiref\handlers.py", line 274, in write
    self.send_headers()
  File "C:\Users\Gina\AppData\Local\Programs\Python\Python36-32\lib\wsgiref\handlers.py", line 332, in send_headers
    self.send_preamble()
  File "C:\Users\Gina\AppData\Local\Programs\Python\Python36-32\lib\wsgiref\handlers.py", line 255, in send_preamble
    ('Date: %s\r\n' % format_date_time(time.time())).encode('iso-8859-1')
  File "C:\Users\Gina\AppData\Local\Programs\Python\Python36-32\lib\wsgiref\handlers.py", line 453, in _write
    result = self.stdout.write(data)
  File "C:\Users\Gina\AppData\Local\Programs\Python\Python36-32\lib\socketserver.py", line 775, in write
    self._sock.sendall(b)
ConnectionAbortedError: [WinError 10053] An established connection was aborted by the software in your host machine
[23/Apr/2020 15:44:35] "GET /admin/ HTTP/1.1" 500 59
----------------------------------------
Exception happened during processing of request from ('127.0.0.1', 56870)
Traceback (most recent call last):
  File "C:\Users\Gina\AppData\Local\Programs\Python\Python36-32\lib\wsgiref\handlers.py", line 138, in run
    self.finish_response()
  File "C:\Users\Gina\AppData\Local\Programs\Python\Python36-32\lib\wsgiref\handlers.py", line 180, in finish_response
    self.write(data)
  File "C:\Users\Gina\AppData\Local\Programs\Python\Python36-32\lib\wsgiref\handlers.py", line 274, in write
    self.send_headers()
  File "C:\Users\Gina\AppData\Local\Programs\Python\Python36-32\lib\wsgiref\handlers.py", line 332, in send_headers
    self.send_preamble()
  File "C:\Users\Gina\AppData\Local\Programs\Python\Python36-32\lib\wsgiref\handlers.py", line 255, in send_preamble
    ('Date: %s\r\n' % format_date_time(time.time())).encode('iso-8859-1')
  File "C:\Users\Gina\AppData\Local\Programs\Python\Python36-32\lib\wsgiref\handlers.py", line 453, in _write
    result = self.stdout.write(data)
  File "C:\Users\Gina\AppData\Local\Programs\Python\Python36-32\lib\socketserver.py", line 775, in write
    self._sock.sendall(b)
ConnectionAbortedError: [WinError 10053] An established connection was aborted by the software in your host machine

During handling of the above exception, another exception occurred:

Traceback (most recent call last):
  File "C:\Users\Gina\AppData\Local\Programs\Python\Python36-32\lib\wsgiref\handlers.py", line 141, in run
    self.handle_error()
  File "C:\Users\Gina\PycharmProjects\Kivy\venv\lib\site-packages\django\core\servers\basehttp.py", line 119, in handle_error
    super().handle_error()
  File "C:\Users\Gina\AppData\Local\Programs\Python\Python36-32\lib\wsgiref\handlers.py", line 368, in handle_error
    self.finish_response()
  File "C:\Users\Gina\AppData\Local\Programs\Python\Python36-32\lib\wsgiref\handlers.py", line 180, in finish_response
    self.write(data)
  File "C:\Users\Gina\AppData\Local\Programs\Python\Python36-32\lib\wsgiref\handlers.py", line 274, in write
    self.send_headers()
  File "C:\Users\Gina\AppData\Local\Programs\Python\Python36-32\lib\wsgiref\handlers.py", line 331, in send_headers
    if not self.origin_server or self.client_is_modern():
  File "C:\Users\Gina\AppData\Local\Programs\Python\Python36-32\lib\wsgiref\handlers.py", line 344, in client_is_modern
    return self.environ['SERVER_PROTOCOL'].upper() != 'HTTP/0.9'
TypeError: 'NoneType' object is not subscriptable

During handling of the above exception, another exception occurred:

Traceback (most recent call last):
  File "C:\Users\Gina\AppData\Local\Programs\Python\Python36-32\lib\socketserver.py", line 639, in process_request_thread
    self.finish_request(request, client_address)
  File "C:\Users\Gina\AppData\Local\Programs\Python\Python36-32\lib\socketserver.py", line 361, in finish_request
    self.RequestHandlerClass(request, client_address, self)
  File "C:\Users\Gina\AppData\Local\Programs\Python\Python36-32\lib\socketserver.py", line 696, in __init__
    self.handle()
  File "C:\Users\Gina\PycharmProjects\Kivy\venv\lib\site-packages\django\core\servers\basehttp.py", line 174, in handle
    self.handle_one_request()
  File "C:\Users\Gina\PycharmProjects\Kivy\venv\lib\site-packages\django\core\servers\basehttp.py", line 197, in handle_one_request
    handler.run(self.server.get_app())
  File "C:\Users\Gina\AppData\Local\Programs\Python\Python36-32\lib\wsgiref\handlers.py", line 144, in run
    self.close()
  File "C:\Users\Gina\PycharmProjects\Kivy\venv\lib\site-packages\django\core\servers\basehttp.py", line 114, in close
    super().close()
  File "C:\Users\Gina\AppData\Local\Programs\Python\Python36-32\lib\wsgiref\simple_server.py", line 35, in close
    self.status.split(' ',1)[0], self.bytes_sent
AttributeError: 'NoneType' object has no attribute 'split'
----------------------------------------
C:\Users\Gina\PycharmProjects\Django-DerekBanas\sampsite\sampsite\urls.py changed, reloading.
Watching for file changes with StatReloader
Performing system checks...

System check identified some issues:

WARNINGS:
?: (urls.W002) Your URL pattern '^/$' has a route beginning with a '/'. Remove this slash as it is unnecessary. If this pattern is targeted in an include(), ensure the include() pattern
 has a trailing '/'.

System check identified 1 issue (0 silenced).

You have 17 unapplied migration(s). Your project may not work properly until you apply the migrations for app(s): admin, auth, contenttypes, sessions.
Run 'python manage.py migrate' to apply them.
April 23, 2020 - 15:46:24
Django version 3.0.5, using settings 'sampsite.settings'
Starting development server at http://127.0.0.1:8000/
Quit the server with CTRL-BREAK.
Not Found: /rootpage
[23/Apr/2020 15:46:32] "GET /rootpage HTTP/1.1" 404 2519
Not Found: /rootpage
[23/Apr/2020 15:46:41] "GET /rootpage HTTP/1.1" 404 2519
Not Found: /rootpage
[23/Apr/2020 15:46:56] "GET /rootpage HTTP/1.1" 404 2519
Not Found: /
[23/Apr/2020 15:47:04] "GET / HTTP/1.1" 404 2477
Not Found: /
[23/Apr/2020 15:47:06] "GET / HTTP/1.1" 404 2477
C:\Users\Gina\PycharmProjects\Django-DerekBanas\sampsite\sampsite\urls.py changed, reloading.
Watching for file changes with StatReloader
Performing system checks...

System check identified no issues (0 silenced).

You have 17 unapplied migration(s). Your project may not work properly until you apply the migrations for app(s): admin, auth, contenttypes, sessions.
Run 'python manage.py migrate' to apply them.
April 23, 2020 - 15:47:35
Django version 3.0.5, using settings 'sampsite.settings'
Starting development server at http://127.0.0.1:8000/
Quit the server with CTRL-BREAK.
[23/Apr/2020 15:47:36] "GET / HTTP/1.1" 200 23
[23/Apr/2020 15:48:35] "GET /random/1000 HTTP/1.1" 200 45
C:\Users\Gina\PycharmProjects\Django-DerekBanas\sampsite\sampsite\urls.py changed, reloading.
Watching for file changes with StatReloader
Performing system checks...

Exception in thread django-main-thread:
Traceback (most recent call last):
  File "C:\Users\Gina\AppData\Local\Programs\Python\Python36-32\lib\threading.py", line 916, in _bootstrap_inner
    self.run()
  File "C:\Users\Gina\AppData\Local\Programs\Python\Python36-32\lib\threading.py", line 864, in run
    self._target(*self._args, **self._kwargs)
  File "C:\Users\Gina\PycharmProjects\Kivy\venv\lib\site-packages\django\utils\autoreload.py", line 53, in wrapper
    fn(*args, **kwargs)
  File "C:\Users\Gina\PycharmProjects\Kivy\venv\lib\site-packages\django\core\management\commands\runserver.py", line 117, in inner_run
    self.check(display_num_errors=True)
  File "C:\Users\Gina\PycharmProjects\Kivy\venv\lib\site-packages\django\core\management\base.py", line 395, in check
    include_deployment_checks=include_deployment_checks,
  File "C:\Users\Gina\PycharmProjects\Kivy\venv\lib\site-packages\django\core\management\base.py", line 382, in _run_checks
    return checks.run_checks(**kwargs)
  File "C:\Users\Gina\PycharmProjects\Kivy\venv\lib\site-packages\django\core\checks\registry.py", line 72, in run_checks
    new_errors = check(app_configs=app_configs)
  File "C:\Users\Gina\PycharmProjects\Kivy\venv\lib\site-packages\django\core\checks\urls.py", line 40, in check_url_namespaces_unique
    all_namespaces = _load_all_namespaces(resolver)
  File "C:\Users\Gina\PycharmProjects\Kivy\venv\lib\site-packages\django\core\checks\urls.py", line 57, in _load_all_namespaces
    url_patterns = getattr(resolver, 'url_patterns', [])
  File "C:\Users\Gina\PycharmProjects\Kivy\venv\lib\site-packages\django\utils\functional.py", line 48, in __get__
    res = instance.__dict__[self.name] = self.func(instance)
  File "C:\Users\Gina\PycharmProjects\Kivy\venv\lib\site-packages\django\urls\resolvers.py", line 588, in url_patterns
    patterns = getattr(self.urlconf_module, "urlpatterns", self.urlconf_module)
  File "C:\Users\Gina\PycharmProjects\Kivy\venv\lib\site-packages\django\utils\functional.py", line 48, in __get__
    res = instance.__dict__[self.name] = self.func(instance)
  File "C:\Users\Gina\PycharmProjects\Kivy\venv\lib\site-packages\django\urls\resolvers.py", line 581, in urlconf_module
    return import_module(self.urlconf_name)
  File "C:\Users\Gina\AppData\Local\Programs\Python\Python36-32\lib\importlib\__init__.py", line 126, in import_module
    return _bootstrap._gcd_import(name[level:], package, level)
  File "<frozen importlib._bootstrap>", line 994, in _gcd_import
  File "<frozen importlib._bootstrap>", line 971, in _find_and_load
  File "<frozen importlib._bootstrap>", line 955, in _find_and_load_unlocked
  File "<frozen importlib._bootstrap>", line 665, in _load_unlocked
  File "<frozen importlib._bootstrap_external>", line 674, in exec_module
  File "<frozen importlib._bootstrap_external>", line 781, in get_code
  File "<frozen importlib._bootstrap_external>", line 741, in source_to_code
  File "<frozen importlib._bootstrap>", line 219, in _call_with_frames_removed
  File "C:\Users\Gina\PycharmProjects\Django-DerekBanas\sampsite\sampsite\urls.py", line 44
    re_path(r'^random'int('\d+/')$)
                        ^
SyntaxError: invalid syntax

C:\Users\Gina\PycharmProjects\Django-DerekBanas\sampsite\sampsite\urls.py changed, reloading.
Watching for file changes with StatReloader
Performing system checks...

System check identified no issues (0 silenced).

You have 17 unapplied migration(s). Your project may not work properly until you apply the migrations for app(s): admin, auth, contenttypes, sessions.
Run 'python manage.py migrate' to apply them.
April 23, 2020 - 16:27:44
Django version 3.0.5, using settings 'sampsite.settings'
Starting development server at http://127.0.0.1:8000/
Quit the server with CTRL-BREAK.
C:\Users\Gina\PycharmProjects\Django-DerekBanas\sampsite\sampsite\urls.py changed, reloading.
Watching for file changes with StatReloader
Performing system checks...

System check identified no issues (0 silenced).

You have 17 unapplied migration(s). Your project may not work properly until you apply the migrations for app(s): admin, auth, contenttypes, sessions.
Run 'python manage.py migrate' to apply them.
April 23, 2020 - 16:28:45
Django version 3.0.5, using settings 'sampsite.settings'
Starting development server at http://127.0.0.1:8000/
Quit the server with CTRL-BREAK.
C:\Users\Gina\PycharmProjects\Django-DerekBanas\sampsite\sampsite\urls.py changed, reloading.
Watching for file changes with StatReloader
Performing system checks...

System check identified no issues (0 silenced).

You have 17 unapplied migration(s). Your project may not work properly until you apply the migrations for app(s): admin, auth, contenttypes, sessions.
Run 'python manage.py migrate' to apply them.
April 23, 2020 - 16:32:26
Django version 3.0.5, using settings 'sampsite.settings'
Starting development server at http://127.0.0.1:8000/
Quit the server with CTRL-BREAK.
[23/Apr/2020 16:32:29] "GET /random/1000 HTTP/1.1" 200 47
Not Found: /random/
[23/Apr/2020 16:32:42] "GET /random/ HTTP/1.1" 404 2395
Not Found: /random/
[23/Apr/2020 16:33:16] "GET /random/ HTTP/1.1" 404 2395
Not Found: /random/
[23/Apr/2020 16:46:26] "GET /random/ HTTP/1.1" 404 2395
C:\Users\Gina\PycharmProjects\Django-DerekBanas\sampsite\sampsite\urls.py changed, reloading.
Watching for file changes with StatReloader
Performing system checks...

System check identified no issues (0 silenced).

You have 17 unapplied migration(s). Your project may not work properly until you apply the migrations for app(s): admin, auth, contenttypes, sessions.
Run 'python manage.py migrate' to apply them.
April 23, 2020 - 16:46:33
Django version 3.0.5, using settings 'sampsite.settings'
Starting development server at http://127.0.0.1:8000/
Quit the server with CTRL-BREAK.
[23/Apr/2020 16:46:33] "GET /random/ HTTP/1.1" 200 45
[23/Apr/2020 16:46:49] "GET /random/2000 HTTP/1.1" 200 45
[23/Apr/2020 16:46:56] "GET /random/2000 HTTP/1.1" 200 44
C:\Users\Gina\PycharmProjects\Django-DerekBanas\sampsite\sampsite\urls.py changed, reloading.
Watching for file changes with StatReloader
Performing system checks...

System check identified no issues (0 silenced).

You have 17 unapplied migration(s). Your project may not work properly until you apply the migrations for app(s): admin, auth, contenttypes, sessions.
Run 'python manage.py migrate' to apply them.
April 23, 2020 - 16:48:02
Django version 3.0.5, using settings 'sampsite.settings'
Starting development server at http://127.0.0.1:8000/
Quit the server with CTRL-BREAK.
[23/Apr/2020 16:48:02] "GET /random/2000 HTTP/1.1" 200 47
[23/Apr/2020 16:48:21] "GET /random/ HTTP/1.1" 200 45
C:\Users\Gina\PycharmProjects\Django-DerekBanas\sampsite\sampsite\urls.py changed, reloading.
Watching for file changes with StatReloader
Performing system checks...

System check identified no issues (0 silenced).

You have 17 unapplied migration(s). Your project may not work properly until you apply the migrations for app(s): admin, auth, contenttypes, sessions.
Run 'python manage.py migrate' to apply them.
April 23, 2020 - 16:52:45
Django version 3.0.5, using settings 'sampsite.settings'
Starting development server at http://127.0.0.1:8000/
Quit the server with CTRL-BREAK.
[23/Apr/2020 16:52:46] "GET / HTTP/1.1" 200 23
[23/Apr/2020 16:52:53] "GET /polls/ HTTP/1.1" 200 30
C:\Users\Gina\PycharmProjects\Django-DerekBanas\sampsite\sampsite\settings.py changed, reloading.
Watching for file changes with StatReloader
Performing system checks...

System check identified no issues (0 silenced).

You have 17 unapplied migration(s). Your project may not work properly until you apply the migrations for app(s): admin, auth, contenttypes, sessions.
Run 'python manage.py migrate' to apply them.
April 23, 2020 - 16:59:27
Django version 3.0.5, using settings 'sampsite.settings'
Starting development server at http://127.0.0.1:8000/
Quit the server with CTRL-BREAK.
C:\Users\Gina\PycharmProjects\Django-DerekBanas\sampsite\sampsite\settings.py changed, reloading.
Traceback (most recent call last):
  File "manage.py", line 21, in <module>
    main()
  File "manage.py", line 17, in main
    execute_from_command_line(sys.argv)
  File "C:\Users\Gina\PycharmProjects\Kivy\venv\lib\site-packages\django\core\management\__init__.py", line 401, in execute_from_command_line
    utility.execute()
  File "C:\Users\Gina\PycharmProjects\Kivy\venv\lib\site-packages\django\core\management\__init__.py", line 345, in execute
    settings.INSTALLED_APPS
  File "C:\Users\Gina\PycharmProjects\Kivy\venv\lib\site-packages\django\conf\__init__.py", line 76, in __getattr__
    self._setup(name)
  File "C:\Users\Gina\PycharmProjects\Kivy\venv\lib\site-packages\django\conf\__init__.py", line 63, in _setup
    self._wrapped = Settings(settings_module)
  File "C:\Users\Gina\PycharmProjects\Kivy\venv\lib\site-packages\django\conf\__init__.py", line 142, in __init__
    mod = importlib.import_module(self.SETTINGS_MODULE)
  File "C:\Users\Gina\AppData\Local\Programs\Python\Python36-32\lib\importlib\__init__.py", line 126, in import_module
    return _bootstrap._gcd_import(name[level:], package, level)
  File "<frozen importlib._bootstrap>", line 994, in _gcd_import
  File "<frozen importlib._bootstrap>", line 971, in _find_and_load
  File "<frozen importlib._bootstrap>", line 955, in _find_and_load_unlocked
  File "<frozen importlib._bootstrap>", line 665, in _load_unlocked
  File "<frozen importlib._bootstrap_external>", line 674, in exec_module
  File "<frozen importlib._bootstrap_external>", line 781, in get_code
  File "<frozen importlib._bootstrap_external>", line 741, in source_to_code
  File "<frozen importlib._bootstrap>", line 219, in _call_with_frames_removed
  File "C:\Users\Gina\PycharmProjects\Django-DerekBanas\sampsite\sampsite\settings.py", line 77
    django.db.backends.
                      ^
SyntaxError: invalid syntax

(venv) C:\Users\Gina\PycharmProjects\Django-DerekBanas\sampsite>python manage.py runserver
Watching for file changes with StatReloader
Performing system checks...

System check identified no issues (0 silenced).
                                               April 23, 2020 - 19:46:00
Django version 3.0.5, using settings 'sampsite.settings'
Starting development server at http://127.0.0.1:8000/
Quit the server with CTRL-BREAK.
[23/Apr/2020 19:46:14] "GET /random/666 HTTP/1.1" 200 46
C:\Users\Gina\PycharmProjects\Django-DerekBanas\sampsite\polls\models.py changed, reloading.
Watching for file changes with StatReloader
Performing system checks...

System check identified no issues (0 silenced).
April 23, 2020 - 20:48:15
Django version 3.0.5, using settings 'sampsite.settings'
Starting development server at http://127.0.0.1:8000/
Quit the server with CTRL-BREAK.
C:\Users\Gina\PycharmProjects\Django-DerekBanas\sampsite\polls\models.py changed, reloading.
Watching for file changes with StatReloader
Exception in thread django-main-thread:
Traceback (most recent call last):
  File "C:\Users\Gina\AppData\Local\Programs\Python\Python36-32\lib\threading.py", line 916, i
n _bootstrap_inner
    self.run()
  File "C:\Users\Gina\AppData\Local\Programs\Python\Python36-32\lib\threading.py", line 864, i
n run
    self._target(*self._args, **self._kwargs)
  File "C:\Users\Gina\PycharmProjects\Kivy\venv\lib\site-packages\django\utils\autoreload.py",
 line 53, in wrapper
    fn(*args, **kwargs)
  File "C:\Users\Gina\PycharmProjects\Kivy\venv\lib\site-packages\django\core\management\comma
nds\runserver.py", line 109, in inner_run
    autoreload.raise_last_exception()
  File "C:\Users\Gina\PycharmProjects\Kivy\venv\lib\site-packages\django\utils\autoreload.py",
 line 76, in raise_last_exception
    raise _exception[1]
  File "C:\Users\Gina\PycharmProjects\Kivy\venv\lib\site-packages\django\core\management\__ini
t__.py", line 357, in execute
    autoreload.check_errors(django.setup)()
  File "C:\Users\Gina\PycharmProjects\Kivy\venv\lib\site-packages\django\utils\autoreload.py",
 line 53, in wrapper
    fn(*args, **kwargs)
  File "C:\Users\Gina\PycharmProjects\Kivy\venv\lib\site-packages\django\__init__.py", line 24
, in setup
    apps.populate(settings.INSTALLED_APPS)
  File "C:\Users\Gina\PycharmProjects\Kivy\venv\lib\site-packages\django\apps\registry.py", li
ne 114, in populate
    app_config.import_models()
  File "C:\Users\Gina\PycharmProjects\Kivy\venv\lib\site-packages\django\apps\config.py", line
 211, in import_models
    self.models_module = import_module(models_module_name)
  File "C:\Users\Gina\AppData\Local\Programs\Python\Python36-32\lib\importlib\__init__.py", li
ne 126, in import_module
    return _bootstrap._gcd_import(name[level:], package, level)
  File "<frozen importlib._bootstrap>", line 994, in _gcd_import
  File "<frozen importlib._bootstrap>", line 971, in _find_and_load
  File "<frozen importlib._bootstrap>", line 955, in _find_and_load_unlocked
  File "<frozen importlib._bootstrap>", line 665, in _load_unlocked
  File "<frozen importlib._bootstrap_external>", line 674, in exec_module
  File "<frozen importlib._bootstrap_external>", line 781, in get_code
  File "<frozen importlib._bootstrap_external>", line 741, in source_to_code
  File "<frozen importlib._bootstrap>", line 219, in _call_with_frames_removed
  File "C:\Users\Gina\PycharmProjects\Django-DerekBanas\sampsite\polls\models.py", line 24
    class Choice(models.Model):
                              ^
IndentationError: expected an indented block

C:\Users\Gina\PycharmProjects\Django-DerekBanas\sampsite\polls\models.py changed, reloading.
Watching for file changes with StatReloader
Performing system checks...

System check identified no issues (0 silenced).
April 23, 2020 - 21:49:30
Django version 3.0.5, using settings 'sampsite.settings'
Starting development server at http://127.0.0.1:8000/
Quit the server with CTRL-BREAK.
C:\Users\Gina\PycharmProjects\Django-DerekBanas\sampsite\polls\models.py changed, reloading.
Watching for file changes with StatReloader
Performing system checks...

System check identified no issues (0 silenced).
April 23, 2020 - 21:54:16
Django version 3.0.5, using settings 'sampsite.settings'
Starting development server at http://127.0.0.1:8000/
Quit the server with CTRL-BREAK.
C:\Users\Gina\PycharmProjects\Django-DerekBanas\sampsite\polls\models.py changed, reloading.
Watching for file changes with StatReloader
Performing system checks...

System check identified no issues (0 silenced).
April 23, 2020 - 21:54:35
Django version 3.0.5, using settings 'sampsite.settings'
Starting development server at http://127.0.0.1:8000/
Quit the server with CTRL-BREAK.
C:\Users\Gina\PycharmProjects\Django-DerekBanas\sampsite\polls\models.py changed, reloading.
Watching for file changes with StatReloader
Performing system checks...

System check identified no issues (0 silenced).
April 23, 2020 - 21:55:06
Django version 3.0.5, using settings 'sampsite.settings'
Starting development server at http://127.0.0.1:8000/
Quit the server with CTRL-BREAK.
C:\Users\Gina\PycharmProjects\Django-DerekBanas\sampsite\polls\models.py changed, reloading.
Watching for file changes with StatReloader
Performing system checks...

System check identified no issues (0 silenced).
April 23, 2020 - 21:55:21
Django version 3.0.5, using settings 'sampsite.settings'
Starting development server at http://127.0.0.1:8000/
Quit the server with CTRL-BREAK.
C:\Users\Gina\PycharmProjects\Django-DerekBanas\sampsite\polls\models.py changed, reloading.
Watching for file changes with StatReloader
Performing system checks...

System check identified no issues (0 silenced).
April 23, 2020 - 21:56:54
Django version 3.0.5, using settings 'sampsite.settings'
Starting development server at http://127.0.0.1:8000/
Quit the server with CTRL-BREAK.
C:\Users\Gina\PycharmProjects\Django-DerekBanas\sampsite\polls\models.py changed, reloading.
Watching for file changes with StatReloader
Performing system checks...

System check identified no issues (0 silenced).
April 23, 2020 - 22:00:03
Django version 3.0.5, using settings 'sampsite.settings'
Starting development server at http://127.0.0.1:8000/
Quit the server with CTRL-BREAK.
C:\Users\Gina\PycharmProjects\Django-DerekBanas\sampsite\polls\models.py changed, reloading.
Watching for file changes with StatReloader
Performing system checks...



